Workbook

Sheet Conceitos

Sheet Legenda
B2: Classificação | C2: D | D2: Desconhece
C3: B | D3: Bronze
C4: P | D4: Prata
C5: O | D5: Ouro
B6: Preceito | C6: 0 | D6: Desejável
C7: 1 | D7: Obrigatório
B8: Utilização | C8: A | D8: Aplicar
C9: I | D9: Ignorar
C10: N | D10: Não se Aplica

Sheet Matriz_Comportamentos
B2: CATEGORIA | C2: COMPETÊNCIAS | D2: Dev Trainee Backend | F2: Dev Júnior Backend | H2: Dev Pleno Backend | J2: Dev Sênior Backend | M2: Dev Trainee Frontend | O2: Dev Júnior Frontend | Q2: Dev Pleno Frontend | S2: Dev Sênior Frontend | V2: Q.A. Trainee | X2: Q.A. Júnior | Z2: Q.A. Pleno | AB2: Q.A. Sênior | AE2: Devops Trainee | AG2: Devops Júnior | AI2: Devops Pleno | AK2: Devops Sênior
D3: Conceito | E3: Preceito | F3: Conceito | G3: Preceito | H3: Conceito | I3: Preceito | J3: Conceito | K3: Preceito | M3: Conceito | N3: Preceito | O3: Conceito | P3: Preceito | Q3: Conceito | R3: Preceito | S3: Conceito | T3: Preceito | V3: Conceito | W3: Preceito | X3: Conceito | Y3: Preceito | Z3: Conceito | AA3: Preceito | AB3: Conceito | AC3: Preceito | AE3: Conceito | AF3: Preceito | AG3: Conceito | AH3: Preceito | AI3: Conceito | AJ3: Preceito | AK3: Conceito | AL3: Preceito
B5: Comportamentais | C5: Comunicação | D5: B | E5: 0 | F5: B | G5: 0 | H5: P | I5: 0 | J5: O | K5: 0 | M5: B | N5: 0 | O5: B | P5: 0 | Q5: P | R5: 0 | S5: O | T5: 0 | V5: B | W5: 0 | X5: B | Y5: 0 | Z5: P | AA5: 0 | AB5: O | AC5: 0 | AE5: B | AF5: 0 | AG5: B | AH5: 0 | AI5: P | AJ5: 0 | AK5: O | AL5: 0
B6: Comportamentais | C6: Confiança | D6: B | E6: 0 | F6: B | G6: 0 | H6: P | I6: 0 | J6: O | K6: 0 | M6: B | N6: 0 | O6: B | P6: 0 | Q6: P | R6: 0 | S6: O | T6: 0 | V6: B | W6: 0 | X6: B | Y6: 0 | Z6: P | AA6: 0 | AB6: O | AC6: 0 | AE6: B | AF6: 0 | AG6: B | AH6: 0 | AI6: P | AJ6: 0 | AK6: O | AL6: 0
B7: Comportamentais | C7: Desenvolvimento de Pessoas | D7: B | E7: 0 | F7: B | G7: 0 | H7: P | I7: 0 | J7: O | K7: 0 | M7: B | N7: 0 | O7: B | P7: 0 | Q7: P | R7: 0 | S7: O | T7: 0 | V7: B | W7: 0 | X7: B | Y7: 0 | Z7: P | AA7: 0 | AB7: O | AC7: 0 | AE7: B | AF7: 0 | AG7: B | AH7: 0 | AI7: P | AJ7: 0 | AK7: O | AL7: 0
B8: Comportamentais | C8: Comprometimento | D8: B | E8: 0 | F8: B | G8: 0 | H8: P | I8: 0 | J8: O | K8: 0 | M8: B | N8: 0 | O8: B | P8: 0 | Q8: P | R8: 0 | S8: O | T8: 0 | V8: B | W8: 0 | X8: B | Y8: 0 | Z8: P | AA8: 0 | AB8: O | AC8: 0 | AE8: B | AF8: 0 | AG8: B | AH8: 0 | AI8: P | AJ8: 0 | AK8: O | AL8: 0
B9: Comportamentais | C9: Protagonismo | D9: B | E9: 0 | F9: B | G9: 0 | H9: P | I9: 0 | J9: O | K9: 0 | M9: B | N9: 0 | O9: B | P9: 0 | Q9: P | R9: 0 | S9: O | T9: 0 | V9: B | W9: 0 | X9: B | Y9: 0 | Z9: P | AA9: 0 | AB9: O | AC9: 0 | AE9: B | AF9: 0 | AG9: B | AH9: 0 | AI9: P | AJ9: 0 | AK9: O | AL9: 0
B10: Comportamentais | C10: Compromisso com o Cliente | D10: B | E10: 0 | F10: B | G10: 0 | H10: P | I10: 0 | J10: O | K10: 0 | M10: B | N10: 0 | O10: B | P10: 0 | Q10: P | R10: 0 | S10: O | T10: 0 | V10: B | W10: 0 | X10: B | Y10: 0 | Z10: P | AA10: 0 | AB10: O | AC10: 0 | AE10: B | AF10: 0 | AG10: B | AH10: 0 | AI10: P | AJ10: 0 | AK10: O | AL10: 0
B12: Legenda:
B13: Símbolo | C13: Conceito | D13: Conceito Avaliação Desempenho
B14: D | C14: Desconhece | D14: Requer Melhoria
B15: B | C15: Bronze | D15: Está no Caminho
B16: P | C16: Prata | D16: Mandou Bem
B17: O | C17: Ouro | D17: Mandou Muito Bem

Sheet Matriz_Plataforma
B2: Meta 2026 | C2: CATEGORIA | D2: COMPETÊNCIAS | E2: Dev Trainee Backend | G2: Dev Júnior Backend | I2: Dev Pleno Backend | K2: Dev Sênior Backend | N2: Dev Trainee Frontend | P2: Dev Júnior Frontend | R2: Dev Pleno Frontend | T2: Dev Sênior Frontend | W2: Q.A. Trainee | Y2: Q.A. Júnior | AA2: Q.A. Pleno | AC2: Q.A. Sênior | AF2: Devops Trainee | AH2: Devops Júnior | AJ2: Devops Pleno | AL2: Devops Sênior | AO2: Dev Backend | AP2: Dev Frontend | AQ2: Q.A. | AR2: Devops | AT2: PAULO CORREIA CAMARGO JUNIOR | AV2: MARCOS ADRIANO RIBEIRO LIMA | AX2: BRUNA BRANCO | AZ2: EDIMILSON DA SILVA PEREIRA | BB2: GUILHERME ZANELLA HUGEN | BD2: RAFAEL ALDO SEROISKA | BF2: WELLENGTON JOSE MACHADO | BH2: CEDRICK QUADROS COSTA | BJ2: DAVI DOS SANTOS SILVA GONCALVES | BL2: IGOR ALESSANDRO FORGHIERI | BN2: MAURICIO DE SOUZA PERES | BP2: DIEGO DE LIZ | BR2: ADRIEL GOULART DE ABRANJO | BT2: MATHEUS BECKHAUSER NUNES | BV2: GILBERTO MOTA DE OLIVEIRA JUNIOR | BX2: FELIPE HEIDEN MAINES | BZ2: JOÃO VITOR RODRIGUES DE MORAES
E3: Conceito | F3: Preceito | G3: Conceito | H3: Preceito | I3: Conceito | J3: Preceito | K3: Conceito | L3: Preceito | N3: Conceito | O3: Preceito | P3: Conceito | Q3: Preceito | R3: Conceito | S3: Preceito | T3: Conceito | U3: Preceito | W3: Conceito | X3: Preceito | Y3: Conceito | Z3: Preceito | AA3: Conceito | AB3: Preceito | AC3: Conceito | AD3: Preceito | AF3: Conceito | AG3: Preceito | AH3: Conceito | AI3: Preceito | AJ3: Conceito | AK3: Preceito | AL3: Conceito | AM3: Preceito | AT3: =P2 -> Dev Júnior Frontend | AV3: =I2 -> Dev Pleno Backend | AX3: =R2 -> Dev Pleno Frontend | AZ3: =I2 -> Dev Pleno Backend | BB3: =AJ2 -> Devops Pleno | BD3: =AC2 -> Q.A. Sênior | BF3: =Y2 -> Q.A. Júnior | BH3: =K2 -> Dev Sênior Backend | BJ3: =Y2 -> Q.A. Júnior | BL3: =Y2 -> Q.A. Júnior | BN3: =AJ2 -> Devops Pleno | BP3: =T2 -> Dev Sênior Frontend | BR3: =I2 -> Dev Pleno Backend | BT3: =G2 -> Dev Júnior Backend | BV3: =G2 -> Dev Júnior Backend | BX3: =P2 -> Dev Júnior Frontend | BZ3: =G2 -> Dev Júnior Backend
AT4: Nível | AU4: Atinge Meta 2026 | AV4: Nível | AW4: Atinge Meta 2026 | AX4: Nível | AY4: Atinge Meta 2026 | AZ4: Nível | BA4: Atinge Meta 2026 | BB4: Nível | BC4: Atinge Meta 2026 | BD4: Nível | BE4: Atinge Meta 2026 | BF4: Nível | BG4: Atinge Meta 2026 | BH4: Nível | BI4: Atinge Meta 2026 | BJ4: Nível | BK4: Atinge Meta 2026 | BL4: Nível | BM4: Atinge Meta 2026 | BN4: Nível | BO4: Atinge Meta 2026 | BP4: Nível | BQ4: Atinge Meta 2026 | BR4: Nível | BS4: Atinge Meta 2026 | BT4: Nível | BU4: Atinge Meta 2026 | BV4: Nível | BW4: Atinge Meta 2026 | BX4: Nível | BY4: Atinge Meta 2026 | BZ4: Nível | CA4: Atinge Meta 2026
B5: Não | C5: Dev | D5: MultiThread | E5: B | F5: 0 | G5: P | H5: 1 | I5: O | J5: 1 | K5: O | L5: 1 | N5: N | O5: N | P5: N | Q5: N | R5: B | S5: 1 | T5: P | U5: 1 | W5: N | X5: N | Y5: N | Z5: N | AA5: N | AB5: N | AC5: N | AD5: N | AF5: N | AG5: N | AH5: N | AI5: N | AJ5: N | AK5: N | AL5: N | AM5: N | AO5: A | AP5: A | AQ5: I | AR5: I | AT5: P | AU5: =IF($P5="N", "N", IF($B5="Não", "Sim", IF(OR( AT5=$P5, AND($P5="B", OR(AT5="B", AT5="P", AT5="O")), AND($P5="P", OR(AT5="P", AT5="O")), AND($P5="O", AT5="O")), "Sim", "Não") ) ) -> N | AV5: O | AW5: =IF($I5="N", "N", IF($B5="Não", "Sim", IF(OR( AV5=$I5, AND($I5="B", OR(AV5="B", AV5="P", AV5="O")), AND($I5="P", OR(AV5="P", AV5="O")), AND($I5="O", AV5="O")), "Sim", "Não") ) ) -> Sim | AX5: B | AY5: =IF($R5="N", "N", IF($B5="Não", "Sim", IF(OR( AX5=$R5, AND($R5="B", OR(AX5="B", AX5="P", AX5="O")), AND($R5="P", OR(AX5="P", AX5="O")), AND($R5="O", AX5="O")), "Sim", "Não") ) ) -> Sim | AZ5: B | BA5: =IF($I5="N", "N", IF($B5="Não", "Sim", IF(OR( AZ5=$I5, AND($I5="B", OR(AZ5="B", AZ5="P", AZ5="O")), AND($I5="P", OR(AZ5="P", AZ5="O")), AND($I5="O", AZ5="O")), "Sim", "Não") ) ) -> Sim | BB5: N | BC5: =IF($AJ5="N", "N", IF($B5="Não", "Sim", IF(OR( BB5=$AJ5, AND($AJ5="B", OR(BB5="B", BB5="P", BB5="O")), AND($AJ5="P", OR(BB5="P", BB5="O")), AND($AJ5="O", BB5="O")), "Sim", "Não") ) ) -> N | BD5: N | BE5: =IF($AC5="N", "N", IF($B5="Não", "Sim", IF(OR( BD5=$AC5, AND($AC5="B", OR(BD5="B", BD5="P", BD5="O")), AND($AC5="P", OR(BD5="P", BD5="O")), AND($AC5="O", BD5="O")), "Sim", "Não") ) ) -> N | BF5: N | BG5: =IF($Y5="N", "N", IF($B5="Não", "Sim", IF(OR( BF5=$Y5, AND($Y5="B", OR(BF5="B", BF5="P", BF5="O")), AND($Y5="P", OR(BF5="P", BF5="O")), AND($Y5="O", BF5="O")), "Sim", "Não") ) ) -> N | BH5: O | BI5: =IF($K5="N", "N", IF($B5="Não", "Sim", IF(OR( BH5=$K5, AND($K5="B", OR(BH5="B", BH5="P", BH5="O")), AND($K5="P", OR(BH5="P", BH5="O")), AND($K5="O", BH5="O")), "Sim", "Não") ) ) -> Sim | BJ5: N | BK5: =IF($Y5="N", "N", IF($B5="Não", "Sim", IF(OR( BJ5=$Y5, AND($Y5="B", OR(BJ5="B", BJ5="P", BJ5="O")), AND($Y5="P", OR(BJ5="P", BJ5="O")), AND($Y5="O", BJ5="O")), "Sim", "Não") ) ) -> N | BL5: N | BM5: =IF($Y5="N", "N", IF($B5="Não", "Sim", IF(OR( BL5=$Y5, AND($Y5="B", OR(BL5="B", BL5="P", BL5="O")), AND($Y5="P", OR(BL5="P", BL5="O")), AND($Y5="O", BL5="O")), "Sim", "Não") ) ) -> N | BN5: N | BO5: =IF($AJ5="N", "N", IF($B5="Não", "Sim", IF(OR( BN5=$AJ5, AND($AJ5="B", OR(BN5="B", BN5="P", BN5="O")), AND($AJ5="P", OR(BN5="P", BN5="O")), AND($AJ5="O", BN5="O")), "Sim", "Não") ) ) -> N | BP5: P | BQ5: =IF($T5="N", "N", IF($B5="Não", "Sim", IF(OR( BP5=$T5, AND($T5="B", OR(BP5="B", BP5="P", BP5="O")), AND($T5="P", OR(BP5="P", BP5="O")), AND($T5="O", BP5="O")), "Sim", "Não") ) ) -> Sim | BR5: O | BS5: =IF($I5="N", "N", IF($B5="Não", "Sim", IF(OR( BR5=$I5, AND($I5="B", OR(BR5="B", BR5="P", BR5="O")), AND($I5="P", OR(BR5="P", BR5="O")), AND($I5="O", BR5="O")), "Sim", "Não") ) ) -> Sim | BT5: P | BU5: =IF($G5="N", "N", IF($B5="Não", "Sim", IF(OR( BT5=$G5, AND($G5="B", OR(BT5="B", BT5="P", BT5="O")), AND($G5="P", OR(BT5="P", BT5="O")), AND($G5="O", BT5="O")), "Sim", "Não") ) ) -> Sim | BV5: B | BW5: =IF($G5="N", "N", IF($B5="Não", "Sim", IF(OR( BV5=$G5, AND($G5="B", OR(BV5="B", BV5="P", BV5="O")), AND($G5="P", OR(BV5="P", BV5="O")), AND($G5="O", BV5="O")), "Sim", "Não") ) ) -> Sim | BX5: P | BY5: =IF($P5="N", "N", IF($B5="Não", "Sim", IF(OR( BX5=$P5, AND($P5="B", OR(BX5="B", BX5="P", BX5="O")), AND($P5="P", OR(BX5="P", BX5="O")), AND($P5="O", BX5="O")), "Sim", "Não") ) ) -> N | BZ5: B | CA5: =IF($G5="N", "N", IF($B5="Não", "Sim", IF(OR( BZ5=$G5, AND($G5="B", OR(BZ5="B", BZ5="P", BZ5="O")), AND($G5="P", OR(BZ5="P", BZ5="O")), AND($G5="O", BZ5="O")), "Sim", "Não") ) ) -> Sim
B6: Não | C6: Dev | D6: DDD (Domain Driven Design) | E6: B | F6: 0 | G6: B | H6: 0 | I6: B | J6: 0 | K6: P | L6: 1 | N6: N | O6: N | P6: N | Q6: N | R6: B | S6: 0 | T6: P | U6: 1 | W6: N | X6: N | Y6: N | Z6: N | AA6: N | AB6: N | AC6: N | AD6: N | AF6: N | AG6: N | AH6: N | AI6: N | AJ6: N | AK6: N | AL6: N | AM6: N | AO6: A | AP6: A | AQ6: I | AR6: I | AT6: P | AU6: =IF($P6="N", "N", IF($B6="Não", "Sim", IF(OR( AT6=$P6, AND($P6="B", OR(AT6="B", AT6="P", AT6="O")), AND($P6="P", OR(AT6="P", AT6="O")), AND($P6="O", AT6="O")), "Sim", "Não") ) ) -> N | AV6: O | AW6: =IF($I6="N", "N", IF($B6="Não", "Sim", IF(OR( AV6=$I6, AND($I6="B", OR(AV6="B", AV6="P", AV6="O")), AND($I6="P", OR(AV6="P", AV6="O")), AND($I6="O", AV6="O")), "Sim", "Não") ) ) -> Sim | AX6: B | AY6: =IF($R6="N", "N", IF($B6="Não", "Sim", IF(OR( AX6=$R6, AND($R6="B", OR(AX6="B", AX6="P", AX6="O")), AND($R6="P", OR(AX6="P", AX6="O")), AND($R6="O", AX6="O")), "Sim", "Não") ) ) -> Sim | AZ6: B | BA6: =IF($I6="N", "N", IF($B6="Não", "Sim", IF(OR( AZ6=$I6, AND($I6="B", OR(AZ6="B", AZ6="P", AZ6="O")), AND($I6="P", OR(AZ6="P", AZ6="O")), AND($I6="O", AZ6="O")), "Sim", "Não") ) ) -> Sim | BB6: N | BC6: =IF($AJ6="N", "N", IF($B6="Não", "Sim", IF(OR( BB6=$AJ6, AND($AJ6="B", OR(BB6="B", BB6="P", BB6="O")), AND($AJ6="P", OR(BB6="P", BB6="O")), AND($AJ6="O", BB6="O")), "Sim", "Não") ) ) -> N | BD6: N | BE6: =IF($AC6="N", "N", IF($B6="Não", "Sim", IF(OR( BD6=$AC6, AND($AC6="B", OR(BD6="B", BD6="P", BD6="O")), AND($AC6="P", OR(BD6="P", BD6="O")), AND($AC6="O", BD6="O")), "Sim", "Não") ) ) -> N | BF6: N | BG6: =IF($Y6="N", "N", IF($B6="Não", "Sim", IF(OR( BF6=$Y6, AND($Y6="B", OR(BF6="B", BF6="P", BF6="O")), AND($Y6="P", OR(BF6="P", BF6="O")), AND($Y6="O", BF6="O")), "Sim", "Não") ) ) -> N | BH6: P | BI6: =IF($K6="N", "N", IF($B6="Não", "Sim", IF(OR( BH6=$K6, AND($K6="B", OR(BH6="B", BH6="P", BH6="O")), AND($K6="P", OR(BH6="P", BH6="O")), AND($K6="O", BH6="O")), "Sim", "Não") ) ) -> Sim | BJ6: N | BK6: =IF($Y6="N", "N", IF($B6="Não", "Sim", IF(OR( BJ6=$Y6, AND($Y6="B", OR(BJ6="B", BJ6="P", BJ6="O")), AND($Y6="P", OR(BJ6="P", BJ6="O")), AND($Y6="O", BJ6="O")), "Sim", "Não") ) ) -> N | BL6: N | BM6: =IF($Y6="N", "N", IF($B6="Não", "Sim", IF(OR( BL6=$Y6, AND($Y6="B", OR(BL6="B", BL6="P", BL6="O")), AND($Y6="P", OR(BL6="P", BL6="O")), AND($Y6="O", BL6="O")), "Sim", "Não") ) ) -> N | BN6: N | BO6: =IF($AJ6="N", "N", IF($B6="Não", "Sim", IF(OR( BN6=$AJ6, AND($AJ6="B", OR(BN6="B", BN6="P", BN6="O")), AND($AJ6="P", OR(BN6="P", BN6="O")), AND($AJ6="O", BN6="O")), "Sim", "Não") ) ) -> N | BP6: P | BQ6: =IF($T6="N", "N", IF($B6="Não", "Sim", IF(OR( BP6=$T6, AND($T6="B", OR(BP6="B", BP6="P", BP6="O")), AND($T6="P", OR(BP6="P", BP6="O")), AND($T6="O", BP6="O")), "Sim", "Não") ) ) -> Sim | BR6: P | BS6: =IF($I6="N", "N", IF($B6="Não", "Sim", IF(OR( BR6=$I6, AND($I6="B", OR(BR6="B", BR6="P", BR6="O")), AND($I6="P", OR(BR6="P", BR6="O")), AND($I6="O", BR6="O")), "Sim", "Não") ) ) -> Sim | BT6: P | BU6: =IF($G6="N", "N", IF($B6="Não", "Sim", IF(OR( BT6=$G6, AND($G6="B", OR(BT6="B", BT6="P", BT6="O")), AND($G6="P", OR(BT6="P", BT6="O")), AND($G6="O", BT6="O")), "Sim", "Não") ) ) -> Sim | BV6: P | BW6: =IF($G6="N", "N", IF($B6="Não", "Sim", IF(OR( BV6=$G6, AND($G6="B", OR(BV6="B", BV6="P", BV6="O")), AND($G6="P", OR(BV6="P", BV6="O")), AND($G6="O", BV6="O")), "Sim", "Não") ) ) -> Sim | BX6: P | BY6: =IF($P6="N", "N", IF($B6="Não", "Sim", IF(OR( BX6=$P6, AND($P6="B", OR(BX6="B", BX6="P", BX6="O")), AND($P6="P", OR(BX6="P", BX6="O")), AND($P6="O", BX6="O")), "Sim", "Não") ) ) -> N | BZ6: P | CA6: =IF($G6="N", "N", IF($B6="Não", "Sim", IF(OR( BZ6=$G6, AND($G6="B", OR(BZ6="B", BZ6="P", BZ6="O")), AND($G6="P", OR(BZ6="P", BZ6="O")), AND($G6="O", BZ6="O")), "Sim", "Não") ) ) -> Sim
B7: Não | C7: Dev | D7: Microsserviços | E7: B | F7: 0 | G7: B | H7: 0 | I7: P | J7: 1 | K7: O | L7: 1 | N7: N | O7: N | P7: N | Q7: N | R7: B | S7: 1 | T7: P | U7: 1 | W7: N | X7: N | Y7: N | Z7: N | AA7: N | AB7: N | AC7: N | AD7: N | AF7: N | AG7: N | AH7: N | AI7: N | AJ7: N | AK7: N | AL7: N | AM7: N | AO7: A | AP7: A | AQ7: I | AR7: I | AT7: P | AU7: =IF($P7="N", "N", IF($B7="Não", "Sim", IF(OR( AT7=$P7, AND($P7="B", OR(AT7="B", AT7="P", AT7="O")), AND($P7="P", OR(AT7="P", AT7="O")), AND($P7="O", AT7="O")), "Sim", "Não") ) ) -> N | AV7: P | AW7: =IF($I7="N", "N", IF($B7="Não", "Sim", IF(OR( AV7=$I7, AND($I7="B", OR(AV7="B", AV7="P", AV7="O")), AND($I7="P", OR(AV7="P", AV7="O")), AND($I7="O", AV7="O")), "Sim", "Não") ) ) -> Sim | AX7: P | AY7: =IF($R7="N", "N", IF($B7="Não", "Sim", IF(OR( AX7=$R7, AND($R7="B", OR(AX7="B", AX7="P", AX7="O")), AND($R7="P", OR(AX7="P", AX7="O")), AND($R7="O", AX7="O")), "Sim", "Não") ) ) -> Sim | AZ7: P | BA7: =IF($I7="N", "N", IF($B7="Não", "Sim", IF(OR( AZ7=$I7, AND($I7="B", OR(AZ7="B", AZ7="P", AZ7="O")), AND($I7="P", OR(AZ7="P", AZ7="O")), AND($I7="O", AZ7="O")), "Sim", "Não") ) ) -> Sim | BB7: N | BC7: =IF($AJ7="N", "N", IF($B7="Não", "Sim", IF(OR( BB7=$AJ7, AND($AJ7="B", OR(BB7="B", BB7="P", BB7="O")), AND($AJ7="P", OR(BB7="P", BB7="O")), AND($AJ7="O", BB7="O")), "Sim", "Não") ) ) -> N | BD7: N | BE7: =IF($AC7="N", "N", IF($B7="Não", "Sim", IF(OR( BD7=$AC7, AND($AC7="B", OR(BD7="B", BD7="P", BD7="O")), AND($AC7="P", OR(BD7="P", BD7="O")), AND($AC7="O", BD7="O")), "Sim", "Não") ) ) -> N | BF7: N | BG7: =IF($Y7="N", "N", IF($B7="Não", "Sim", IF(OR( BF7=$Y7, AND($Y7="B", OR(BF7="B", BF7="P", BF7="O")), AND($Y7="P", OR(BF7="P", BF7="O")), AND($Y7="O", BF7="O")), "Sim", "Não") ) ) -> N | BH7: O | BI7: =IF($K7="N", "N", IF($B7="Não", "Sim", IF(OR( BH7=$K7, AND($K7="B", OR(BH7="B", BH7="P", BH7="O")), AND($K7="P", OR(BH7="P", BH7="O")), AND($K7="O", BH7="O")), "Sim", "Não") ) ) -> Sim | BJ7: N | BK7: =IF($Y7="N", "N", IF($B7="Não", "Sim", IF(OR( BJ7=$Y7, AND($Y7="B", OR(BJ7="B", BJ7="P", BJ7="O")), AND($Y7="P", OR(BJ7="P", BJ7="O")), AND($Y7="O", BJ7="O")), "Sim", "Não") ) ) -> N | BL7: N | BM7: =IF($Y7="N", "N", IF($B7="Não", "Sim", IF(OR( BL7=$Y7, AND($Y7="B", OR(BL7="B", BL7="P", BL7="O")), AND($Y7="P", OR(BL7="P", BL7="O")), AND($Y7="O", BL7="O")), "Sim", "Não") ) ) -> N | BN7: N | BO7: =IF($AJ7="N", "N", IF($B7="Não", "Sim", IF(OR( BN7=$AJ7, AND($AJ7="B", OR(BN7="B", BN7="P", BN7="O")), AND($AJ7="P", OR(BN7="P", BN7="O")), AND($AJ7="O", BN7="O")), "Sim", "Não") ) ) -> N | BP7: P | BQ7: =IF($T7="N", "N", IF($B7="Não", "Sim", IF(OR( BP7=$T7, AND($T7="B", OR(BP7="B", BP7="P", BP7="O")), AND($T7="P", OR(BP7="P", BP7="O")), AND($T7="O", BP7="O")), "Sim", "Não") ) ) -> Sim | BR7: O | BS7: =IF($I7="N", "N", IF($B7="Não", "Sim", IF(OR( BR7=$I7, AND($I7="B", OR(BR7="B", BR7="P", BR7="O")), AND($I7="P", OR(BR7="P", BR7="O")), AND($I7="O", BR7="O")), "Sim", "Não") ) ) -> Sim | BT7: B | BU7: =IF($G7="N", "N", IF($B7="Não", "Sim", IF(OR( BT7=$G7, AND($G7="B", OR(BT7="B", BT7="P", BT7="O")), AND($G7="P", OR(BT7="P", BT7="O")), AND($G7="O", BT7="O")), "Sim", "Não") ) ) -> Sim | BV7: B | BW7: =IF($G7="N", "N", IF($B7="Não", "Sim", IF(OR( BV7=$G7, AND($G7="B", OR(BV7="B", BV7="P", BV7="O")), AND($G7="P", OR(BV7="P", BV7="O")), AND($G7="O", BV7="O")), "Sim", "Não") ) ) -> Sim | BX7: P | BY7: =IF($P7="N", "N", IF($B7="Não", "Sim", IF(OR( BX7=$P7, AND($P7="B", OR(BX7="B", BX7="P", BX7="O")), AND($P7="P", OR(BX7="P", BX7="O")), AND($P7="O", BX7="O")), "Sim", "Não") ) ) -> N | BZ7: P | CA7: =IF($G7="N", "N", IF($B7="Não", "Sim", IF(OR( BZ7=$G7, AND($G7="B", OR(BZ7="B", BZ7="P", BZ7="O")), AND($G7="P", OR(BZ7="P", BZ7="O")), AND($G7="O", BZ7="O")), "Sim", "Não") ) ) -> Sim
B8: Não | C8: Dev | D8: Sistema de gerenciamento de Mensageria | E8: B | F8: 0 | G8: B | H8: 0 | I8: P | J8: 1 | K8: O | L8: 1 | N8: B | O8: 0 | P8: B | Q8: 0 | R8: P | S8: 1 | T8: O | U8: 1 | W8: N | X8: N | Y8: N | Z8: N | AA8: N | AB8: N | AC8: N | AD8: N | AF8: N | AG8: N | AH8: N | AI8: N | AJ8: N | AK8: N | AL8: N | AM8: N | AO8: A | AP8: A | AQ8: I | AR8: I | AT8: P | AU8: =IF($P8="N", "N", IF($B8="Não", "Sim", IF(OR( AT8=$P8, AND($P8="B", OR(AT8="B", AT8="P", AT8="O")), AND($P8="P", OR(AT8="P", AT8="O")), AND($P8="O", AT8="O")), "Sim", "Não") ) ) -> Sim | AV8: P | AW8: =IF($I8="N", "N", IF($B8="Não", "Sim", IF(OR( AV8=$I8, AND($I8="B", OR(AV8="B", AV8="P", AV8="O")), AND($I8="P", OR(AV8="P", AV8="O")), AND($I8="O", AV8="O")), "Sim", "Não") ) ) -> Sim | AX8: P | AY8: =IF($R8="N", "N", IF($B8="Não", "Sim", IF(OR( AX8=$R8, AND($R8="B", OR(AX8="B", AX8="P", AX8="O")), AND($R8="P", OR(AX8="P", AX8="O")), AND($R8="O", AX8="O")), "Sim", "Não") ) ) -> Sim | AZ8: B | BA8: =IF($I8="N", "N", IF($B8="Não", "Sim", IF(OR( AZ8=$I8, AND($I8="B", OR(AZ8="B", AZ8="P", AZ8="O")), AND($I8="P", OR(AZ8="P", AZ8="O")), AND($I8="O", AZ8="O")), "Sim", "Não") ) ) -> Sim | BB8: N | BC8: =IF($AJ8="N", "N", IF($B8="Não", "Sim", IF(OR( BB8=$AJ8, AND($AJ8="B", OR(BB8="B", BB8="P", BB8="O")), AND($AJ8="P", OR(BB8="P", BB8="O")), AND($AJ8="O", BB8="O")), "Sim", "Não") ) ) -> N | BD8: N | BE8: =IF($AC8="N", "N", IF($B8="Não", "Sim", IF(OR( BD8=$AC8, AND($AC8="B", OR(BD8="B", BD8="P", BD8="O")), AND($AC8="P", OR(BD8="P", BD8="O")), AND($AC8="O", BD8="O")), "Sim", "Não") ) ) -> N | BF8: N | BG8: =IF($Y8="N", "N", IF($B8="Não", "Sim", IF(OR( BF8=$Y8, AND($Y8="B", OR(BF8="B", BF8="P", BF8="O")), AND($Y8="P", OR(BF8="P", BF8="O")), AND($Y8="O", BF8="O")), "Sim", "Não") ) ) -> N | BH8: P | BI8: =IF($K8="N", "N", IF($B8="Não", "Sim", IF(OR( BH8=$K8, AND($K8="B", OR(BH8="B", BH8="P", BH8="O")), AND($K8="P", OR(BH8="P", BH8="O")), AND($K8="O", BH8="O")), "Sim", "Não") ) ) -> Sim | BJ8: N | BK8: =IF($Y8="N", "N", IF($B8="Não", "Sim", IF(OR( BJ8=$Y8, AND($Y8="B", OR(BJ8="B", BJ8="P", BJ8="O")), AND($Y8="P", OR(BJ8="P", BJ8="O")), AND($Y8="O", BJ8="O")), "Sim", "Não") ) ) -> N | BL8: N | BM8: =IF($Y8="N", "N", IF($B8="Não", "Sim", IF(OR( BL8=$Y8, AND($Y8="B", OR(BL8="B", BL8="P", BL8="O")), AND($Y8="P", OR(BL8="P", BL8="O")), AND($Y8="O", BL8="O")), "Sim", "Não") ) ) -> N | BN8: N | BO8: =IF($AJ8="N", "N", IF($B8="Não", "Sim", IF(OR( BN8=$AJ8, AND($AJ8="B", OR(BN8="B", BN8="P", BN8="O")), AND($AJ8="P", OR(BN8="P", BN8="O")), AND($AJ8="O", BN8="O")), "Sim", "Não") ) ) -> N | BP8: P | BQ8: =IF($T8="N", "N", IF($B8="Não", "Sim", IF(OR( BP8=$T8, AND($T8="B", OR(BP8="B", BP8="P", BP8="O")), AND($T8="P", OR(BP8="P", BP8="O")), AND($T8="O", BP8="O")), "Sim", "Não") ) ) -> Sim | BR8: P | BS8: =IF($I8="N", "N", IF($B8="Não", "Sim", IF(OR( BR8=$I8, AND($I8="B", OR(BR8="B", BR8="P", BR8="O")), AND($I8="P", OR(BR8="P", BR8="O")), AND($I8="O", BR8="O")), "Sim", "Não") ) ) -> Sim | BT8: B | BU8: =IF($G8="N", "N", IF($B8="Não", "Sim", IF(OR( BT8=$G8, AND($G8="B", OR(BT8="B", BT8="P", BT8="O")), AND($G8="P", OR(BT8="P", BT8="O")), AND($G8="O", BT8="O")), "Sim", "Não") ) ) -> Sim | BV8: B | BW8: =IF($G8="N", "N", IF($B8="Não", "Sim", IF(OR( BV8=$G8, AND($G8="B", OR(BV8="B", BV8="P", BV8="O")), AND($G8="P", OR(BV8="P", BV8="O")), AND($G8="O", BV8="O")), "Sim", "Não") ) ) -> Sim | BX8: B | BY8: =IF($P8="N", "N", IF($B8="Não", "Sim", IF(OR( BX8=$P8, AND($P8="B", OR(BX8="B", BX8="P", BX8="O")), AND($P8="P", OR(BX8="P", BX8="O")), AND($P8="O", BX8="O")), "Sim", "Não") ) ) -> Sim | BZ8: P | CA8: =IF($G8="N", "N", IF($B8="Não", "Sim", IF(OR( BZ8=$G8, AND($G8="B", OR(BZ8="B", BZ8="P", BZ8="O")), AND($G8="P", OR(BZ8="P", BZ8="O")), AND($G8="O", BZ8="O")), "Sim", "Não") ) ) -> Sim
B9: Não | C9: Dev | D9: Desenvolvimento de Web API e RESTful API's (Swagger) | E9: B | F9: 0 | G9: B | H9: 0 | I9: P | J9: 1 | K9: O | L9: 1 | N9: B | O9: 0 | P9: B | Q9: 0 | R9: P | S9: 1 | T9: O | U9: 1 | W9: N | X9: N | Y9: N | Z9: N | AA9: N | AB9: N | AC9: N | AD9: N | AF9: N | AG9: N | AH9: N | AI9: N | AJ9: N | AK9: N | AL9: N | AM9: N | AO9: A | AP9: A | AQ9: I | AR9: I | AT9: P | AU9: =IF($P9="N", "N", IF($B9="Não", "Sim", IF(OR( AT9=$P9, AND($P9="B", OR(AT9="B", AT9="P", AT9="O")), AND($P9="P", OR(AT9="P", AT9="O")), AND($P9="O", AT9="O")), "Sim", "Não") ) ) -> Sim | AV9: P | AW9: =IF($I9="N", "N", IF($B9="Não", "Sim", IF(OR( AV9=$I9, AND($I9="B", OR(AV9="B", AV9="P", AV9="O")), AND($I9="P", OR(AV9="P", AV9="O")), AND($I9="O", AV9="O")), "Sim", "Não") ) ) -> Sim | AX9: P | AY9: =IF($R9="N", "N", IF($B9="Não", "Sim", IF(OR( AX9=$R9, AND($R9="B", OR(AX9="B", AX9="P", AX9="O")), AND($R9="P", OR(AX9="P", AX9="O")), AND($R9="O", AX9="O")), "Sim", "Não") ) ) -> Sim | AZ9: O | BA9: =IF($I9="N", "N", IF($B9="Não", "Sim", IF(OR( AZ9=$I9, AND($I9="B", OR(AZ9="B", AZ9="P", AZ9="O")), AND($I9="P", OR(AZ9="P", AZ9="O")), AND($I9="O", AZ9="O")), "Sim", "Não") ) ) -> Sim | BB9: N | BC9: =IF($AJ9="N", "N", IF($B9="Não", "Sim", IF(OR( BB9=$AJ9, AND($AJ9="B", OR(BB9="B", BB9="P", BB9="O")), AND($AJ9="P", OR(BB9="P", BB9="O")), AND($AJ9="O", BB9="O")), "Sim", "Não") ) ) -> N | BD9: N | BE9: =IF($AC9="N", "N", IF($B9="Não", "Sim", IF(OR( BD9=$AC9, AND($AC9="B", OR(BD9="B", BD9="P", BD9="O")), AND($AC9="P", OR(BD9="P", BD9="O")), AND($AC9="O", BD9="O")), "Sim", "Não") ) ) -> N | BF9: N | BG9: =IF($Y9="N", "N", IF($B9="Não", "Sim", IF(OR( BF9=$Y9, AND($Y9="B", OR(BF9="B", BF9="P", BF9="O")), AND($Y9="P", OR(BF9="P", BF9="O")), AND($Y9="O", BF9="O")), "Sim", "Não") ) ) -> N | BH9: O | BI9: =IF($K9="N", "N", IF($B9="Não", "Sim", IF(OR( BH9=$K9, AND($K9="B", OR(BH9="B", BH9="P", BH9="O")), AND($K9="P", OR(BH9="P", BH9="O")), AND($K9="O", BH9="O")), "Sim", "Não") ) ) -> Sim | BJ9: N | BK9: =IF($Y9="N", "N", IF($B9="Não", "Sim", IF(OR( BJ9=$Y9, AND($Y9="B", OR(BJ9="B", BJ9="P", BJ9="O")), AND($Y9="P", OR(BJ9="P", BJ9="O")), AND($Y9="O", BJ9="O")), "Sim", "Não") ) ) -> N | BL9: N | BM9: =IF($Y9="N", "N", IF($B9="Não", "Sim", IF(OR( BL9=$Y9, AND($Y9="B", OR(BL9="B", BL9="P", BL9="O")), AND($Y9="P", OR(BL9="P", BL9="O")), AND($Y9="O", BL9="O")), "Sim", "Não") ) ) -> N | BN9: N | BO9: =IF($AJ9="N", "N", IF($B9="Não", "Sim", IF(OR( BN9=$AJ9, AND($AJ9="B", OR(BN9="B", BN9="P", BN9="O")), AND($AJ9="P", OR(BN9="P", BN9="O")), AND($AJ9="O", BN9="O")), "Sim", "Não") ) ) -> N | BP9: O | BQ9: =IF($T9="N", "N", IF($B9="Não", "Sim", IF(OR( BP9=$T9, AND($T9="B", OR(BP9="B", BP9="P", BP9="O")), AND($T9="P", OR(BP9="P", BP9="O")), AND($T9="O", BP9="O")), "Sim", "Não") ) ) -> Sim | BR9: O | BS9: =IF($I9="N", "N", IF($B9="Não", "Sim", IF(OR( BR9=$I9, AND($I9="B", OR(BR9="B", BR9="P", BR9="O")), AND($I9="P", OR(BR9="P", BR9="O")), AND($I9="O", BR9="O")), "Sim", "Não") ) ) -> Sim | BT9: B | BU9: =IF($G9="N", "N", IF($B9="Não", "Sim", IF(OR( BT9=$G9, AND($G9="B", OR(BT9="B", BT9="P", BT9="O")), AND($G9="P", OR(BT9="P", BT9="O")), AND($G9="O", BT9="O")), "Sim", "Não") ) ) -> Sim | BV9: P | BW9: =IF($G9="N", "N", IF($B9="Não", "Sim", IF(OR( BV9=$G9, AND($G9="B", OR(BV9="B", BV9="P", BV9="O")), AND($G9="P", OR(BV9="P", BV9="O")), AND($G9="O", BV9="O")), "Sim", "Não") ) ) -> Sim | BX9: P | BY9: =IF($P9="N", "N", IF($B9="Não", "Sim", IF(OR( BX9=$P9, AND($P9="B", OR(BX9="B", BX9="P", BX9="O")), AND($P9="P", OR(BX9="P", BX9="O")), AND($P9="O", BX9="O")), "Sim", "Não") ) ) -> Sim | BZ9: P | CA9: =IF($G9="N", "N", IF($B9="Não", "Sim", IF(OR( BZ9=$G9, AND($G9="B", OR(BZ9="B", BZ9="P", BZ9="O")), AND($G9="P", OR(BZ9="P", BZ9="O")), AND($G9="O", BZ9="O")), "Sim", "Não") ) ) -> Sim
B10: Não | C10: Dev | D10: Dapper | E10: B | F10: 0 | G10: B | H10: 0 | I10: P | J10: 1 | K10: O | L10: 1 | N10: B | O10: 0 | P10: B | Q10: 0 | R10: P | S10: 1 | T10: O | U10: 1 | W10: N | X10: N | Y10: N | Z10: N | AA10: N | AB10: N | AC10: N | AD10: N | AF10: N | AG10: N | AH10: N | AI10: N | AJ10: N | AK10: N | AL10: N | AM10: N | AO10: A | AP10: A | AQ10: I | AR10: I | AT10: P | AU10: =IF($P10="N", "N", IF($B10="Não", "Sim", IF(OR( AT10=$P10, AND($P10="B", OR(AT10="B", AT10="P", AT10="O")), AND($P10="P", OR(AT10="P", AT10="O")), AND($P10="O", AT10="O")), "Sim", "Não") ) ) -> Sim | AV10: P | AW10: =IF($I10="N", "N", IF($B10="Não", "Sim", IF(OR( AV10=$I10, AND($I10="B", OR(AV10="B", AV10="P", AV10="O")), AND($I10="P", OR(AV10="P", AV10="O")), AND($I10="O", AV10="O")), "Sim", "Não") ) ) -> Sim | AX10: P | AY10: =IF($R10="N", "N", IF($B10="Não", "Sim", IF(OR( AX10=$R10, AND($R10="B", OR(AX10="B", AX10="P", AX10="O")), AND($R10="P", OR(AX10="P", AX10="O")), AND($R10="O", AX10="O")), "Sim", "Não") ) ) -> Sim | AZ10: B | BA10: =IF($I10="N", "N", IF($B10="Não", "Sim", IF(OR( AZ10=$I10, AND($I10="B", OR(AZ10="B", AZ10="P", AZ10="O")), AND($I10="P", OR(AZ10="P", AZ10="O")), AND($I10="O", AZ10="O")), "Sim", "Não") ) ) -> Sim | BB10: N | BC10: =IF($AJ10="N", "N", IF($B10="Não", "Sim", IF(OR( BB10=$AJ10, AND($AJ10="B", OR(BB10="B", BB10="P", BB10="O")), AND($AJ10="P", OR(BB10="P", BB10="O")), AND($AJ10="O", BB10="O")), "Sim", "Não") ) ) -> N | BD10: N | BE10: =IF($AC10="N", "N", IF($B10="Não", "Sim", IF(OR( BD10=$AC10, AND($AC10="B", OR(BD10="B", BD10="P", BD10="O")), AND($AC10="P", OR(BD10="P", BD10="O")), AND($AC10="O", BD10="O")), "Sim", "Não") ) ) -> N | BF10: N | BG10: =IF($Y10="N", "N", IF($B10="Não", "Sim", IF(OR( BF10=$Y10, AND($Y10="B", OR(BF10="B", BF10="P", BF10="O")), AND($Y10="P", OR(BF10="P", BF10="O")), AND($Y10="O", BF10="O")), "Sim", "Não") ) ) -> N | BH10: O | BI10: =IF($K10="N", "N", IF($B10="Não", "Sim", IF(OR( BH10=$K10, AND($K10="B", OR(BH10="B", BH10="P", BH10="O")), AND($K10="P", OR(BH10="P", BH10="O")), AND($K10="O", BH10="O")), "Sim", "Não") ) ) -> Sim | BJ10: N | BK10: =IF($Y10="N", "N", IF($B10="Não", "Sim", IF(OR( BJ10=$Y10, AND($Y10="B", OR(BJ10="B", BJ10="P", BJ10="O")), AND($Y10="P", OR(BJ10="P", BJ10="O")), AND($Y10="O", BJ10="O")), "Sim", "Não") ) ) -> N | BL10: N | BM10: =IF($Y10="N", "N", IF($B10="Não", "Sim", IF(OR( BL10=$Y10, AND($Y10="B", OR(BL10="B", BL10="P", BL10="O")), AND($Y10="P", OR(BL10="P", BL10="O")), AND($Y10="O", BL10="O")), "Sim", "Não") ) ) -> N | BN10: N | BO10: =IF($AJ10="N", "N", IF($B10="Não", "Sim", IF(OR( BN10=$AJ10, AND($AJ10="B", OR(BN10="B", BN10="P", BN10="O")), AND($AJ10="P", OR(BN10="P", BN10="O")), AND($AJ10="O", BN10="O")), "Sim", "Não") ) ) -> N | BP10: O | BQ10: =IF($T10="N", "N", IF($B10="Não", "Sim", IF(OR( BP10=$T10, AND($T10="B", OR(BP10="B", BP10="P", BP10="O")), AND($T10="P", OR(BP10="P", BP10="O")), AND($T10="O", BP10="O")), "Sim", "Não") ) ) -> Sim | BR10: O | BS10: =IF($I10="N", "N", IF($B10="Não", "Sim", IF(OR( BR10=$I10, AND($I10="B", OR(BR10="B", BR10="P", BR10="O")), AND($I10="P", OR(BR10="P", BR10="O")), AND($I10="O", BR10="O")), "Sim", "Não") ) ) -> Sim | BT10: B | BU10: =IF($G10="N", "N", IF($B10="Não", "Sim", IF(OR( BT10=$G10, AND($G10="B", OR(BT10="B", BT10="P", BT10="O")), AND($G10="P", OR(BT10="P", BT10="O")), AND($G10="O", BT10="O")), "Sim", "Não") ) ) -> Sim | BV10: B | BW10: =IF($G10="N", "N", IF($B10="Não", "Sim", IF(OR( BV10=$G10, AND($G10="B", OR(BV10="B", BV10="P", BV10="O")), AND($G10="P", OR(BV10="P", BV10="O")), AND($G10="O", BV10="O")), "Sim", "Não") ) ) -> Sim | BX10: B | BY10: =IF($P10="N", "N", IF($B10="Não", "Sim", IF(OR( BX10=$P10, AND($P10="B", OR(BX10="B", BX10="P", BX10="O")), AND($P10="P", OR(BX10="P", BX10="O")), AND($P10="O", BX10="O")), "Sim", "Não") ) ) -> Sim | BZ10: O | CA10: =IF($G10="N", "N", IF($B10="Não", "Sim", IF(OR( BZ10=$G10, AND($G10="B", OR(BZ10="B", BZ10="P", BZ10="O")), AND($G10="P", OR(BZ10="P", BZ10="O")), AND($G10="O", BZ10="O")), "Sim", "Não") ) ) -> Sim
B11: Não | C11: Dev | D11: Testes Integrados automatizados | E11: B | F11: 0 | G11: B | H11: 0 | I11: P | J11: 1 | K11: P | L11: 1 | N11: N | O11: N | P11: N | Q11: N | R11: P | S11: 1 | T11: P | U11: 1 | W11: N | X11: N | Y11: N | Z11: N | AA11: N | AB11: N | AC11: N | AD11: N | AF11: N | AG11: N | AH11: N | AI11: N | AJ11: N | AK11: N | AL11: N | AM11: N | AO11: A | AP11: A | AQ11: I | AR11: I | AT11: P | AU11: =IF($P11="N", "N", IF($B11="Não", "Sim", IF(OR( AT11=$P11, AND($P11="B", OR(AT11="B", AT11="P", AT11="O")), AND($P11="P", OR(AT11="P", AT11="O")), AND($P11="O", AT11="O")), "Sim", "Não") ) ) -> N | AV11: P | AW11: =IF($I11="N", "N", IF($B11="Não", "Sim", IF(OR( AV11=$I11, AND($I11="B", OR(AV11="B", AV11="P", AV11="O")), AND($I11="P", OR(AV11="P", AV11="O")), AND($I11="O", AV11="O")), "Sim", "Não") ) ) -> Sim | AX11: P | AY11: =IF($R11="N", "N", IF($B11="Não", "Sim", IF(OR( AX11=$R11, AND($R11="B", OR(AX11="B", AX11="P", AX11="O")), AND($R11="P", OR(AX11="P", AX11="O")), AND($R11="O", AX11="O")), "Sim", "Não") ) ) -> Sim | AZ11: B | BA11: =IF($I11="N", "N", IF($B11="Não", "Sim", IF(OR( AZ11=$I11, AND($I11="B", OR(AZ11="B", AZ11="P", AZ11="O")), AND($I11="P", OR(AZ11="P", AZ11="O")), AND($I11="O", AZ11="O")), "Sim", "Não") ) ) -> Sim | BB11: N | BC11: =IF($AJ11="N", "N", IF($B11="Não", "Sim", IF(OR( BB11=$AJ11, AND($AJ11="B", OR(BB11="B", BB11="P", BB11="O")), AND($AJ11="P", OR(BB11="P", BB11="O")), AND($AJ11="O", BB11="O")), "Sim", "Não") ) ) -> N | BD11: N | BE11: =IF($AC11="N", "N", IF($B11="Não", "Sim", IF(OR( BD11=$AC11, AND($AC11="B", OR(BD11="B", BD11="P", BD11="O")), AND($AC11="P", OR(BD11="P", BD11="O")), AND($AC11="O", BD11="O")), "Sim", "Não") ) ) -> N | BF11: N | BG11: =IF($Y11="N", "N", IF($B11="Não", "Sim", IF(OR( BF11=$Y11, AND($Y11="B", OR(BF11="B", BF11="P", BF11="O")), AND($Y11="P", OR(BF11="P", BF11="O")), AND($Y11="O", BF11="O")), "Sim", "Não") ) ) -> N | BH11: P | BI11: =IF($K11="N", "N", IF($B11="Não", "Sim", IF(OR( BH11=$K11, AND($K11="B", OR(BH11="B", BH11="P", BH11="O")), AND($K11="P", OR(BH11="P", BH11="O")), AND($K11="O", BH11="O")), "Sim", "Não") ) ) -> Sim | BJ11: N | BK11: =IF($Y11="N", "N", IF($B11="Não", "Sim", IF(OR( BJ11=$Y11, AND($Y11="B", OR(BJ11="B", BJ11="P", BJ11="O")), AND($Y11="P", OR(BJ11="P", BJ11="O")), AND($Y11="O", BJ11="O")), "Sim", "Não") ) ) -> N | BL11: N | BM11: =IF($Y11="N", "N", IF($B11="Não", "Sim", IF(OR( BL11=$Y11, AND($Y11="B", OR(BL11="B", BL11="P", BL11="O")), AND($Y11="P", OR(BL11="P", BL11="O")), AND($Y11="O", BL11="O")), "Sim", "Não") ) ) -> N | BN11: N | BO11: =IF($AJ11="N", "N", IF($B11="Não", "Sim", IF(OR( BN11=$AJ11, AND($AJ11="B", OR(BN11="B", BN11="P", BN11="O")), AND($AJ11="P", OR(BN11="P", BN11="O")), AND($AJ11="O", BN11="O")), "Sim", "Não") ) ) -> N | BP11: P | BQ11: =IF($T11="N", "N", IF($B11="Não", "Sim", IF(OR( BP11=$T11, AND($T11="B", OR(BP11="B", BP11="P", BP11="O")), AND($T11="P", OR(BP11="P", BP11="O")), AND($T11="O", BP11="O")), "Sim", "Não") ) ) -> Sim | BR11: P | BS11: =IF($I11="N", "N", IF($B11="Não", "Sim", IF(OR( BR11=$I11, AND($I11="B", OR(BR11="B", BR11="P", BR11="O")), AND($I11="P", OR(BR11="P", BR11="O")), AND($I11="O", BR11="O")), "Sim", "Não") ) ) -> Sim | BT11: P | BU11: =IF($G11="N", "N", IF($B11="Não", "Sim", IF(OR( BT11=$G11, AND($G11="B", OR(BT11="B", BT11="P", BT11="O")), AND($G11="P", OR(BT11="P", BT11="O")), AND($G11="O", BT11="O")), "Sim", "Não") ) ) -> Sim | BV11: P | BW11: =IF($G11="N", "N", IF($B11="Não", "Sim", IF(OR( BV11=$G11, AND($G11="B", OR(BV11="B", BV11="P", BV11="O")), AND($G11="P", OR(BV11="P", BV11="O")), AND($G11="O", BV11="O")), "Sim", "Não") ) ) -> Sim | BX11: P | BY11: =IF($P11="N", "N", IF($B11="Não", "Sim", IF(OR( BX11=$P11, AND($P11="B", OR(BX11="B", BX11="P", BX11="O")), AND($P11="P", OR(BX11="P", BX11="O")), AND($P11="O", BX11="O")), "Sim", "Não") ) ) -> N | BZ11: O | CA11: =IF($G11="N", "N", IF($B11="Não", "Sim", IF(OR( BZ11=$G11, AND($G11="B", OR(BZ11="B", BZ11="P", BZ11="O")), AND($G11="P", OR(BZ11="P", BZ11="O")), AND($G11="O", BZ11="O")), "Sim", "Não") ) ) -> Sim
B12: Não | C12: Dev | D12: Code Review | E12: N | F12: N | G12: N | H12: N | I12: P | J12: 1 | K12: O | L12: 1 | N12: N | O12: N | P12: N | Q12: N | R12: P | S12: 1 | T12: O | U12: 1 | W12: N | X12: N | Y12: N | Z12: N | AA12: N | AB12: N | AC12: N | AD12: N | AF12: N | AG12: N | AH12: N | AI12: N | AJ12: N | AK12: N | AL12: N | AM12: N | AO12: A | AP12: A | AQ12: I | AR12: I | AT12: P | AU12: =IF($P12="N", "N", IF($B12="Não", "Sim", IF(OR( AT12=$P12, AND($P12="B", OR(AT12="B", AT12="P", AT12="O")), AND($P12="P", OR(AT12="P", AT12="O")), AND($P12="O", AT12="O")), "Sim", "Não") ) ) -> N | AV12: P | AW12: =IF($I12="N", "N", IF($B12="Não", "Sim", IF(OR( AV12=$I12, AND($I12="B", OR(AV12="B", AV12="P", AV12="O")), AND($I12="P", OR(AV12="P", AV12="O")), AND($I12="O", AV12="O")), "Sim", "Não") ) ) -> Sim | AX12: P | AY12: =IF($R12="N", "N", IF($B12="Não", "Sim", IF(OR( AX12=$R12, AND($R12="B", OR(AX12="B", AX12="P", AX12="O")), AND($R12="P", OR(AX12="P", AX12="O")), AND($R12="O", AX12="O")), "Sim", "Não") ) ) -> Sim | AZ12: O | BA12: =IF($I12="N", "N", IF($B12="Não", "Sim", IF(OR( AZ12=$I12, AND($I12="B", OR(AZ12="B", AZ12="P", AZ12="O")), AND($I12="P", OR(AZ12="P", AZ12="O")), AND($I12="O", AZ12="O")), "Sim", "Não") ) ) -> Sim | BB12: N | BC12: =IF($AJ12="N", "N", IF($B12="Não", "Sim", IF(OR( BB12=$AJ12, AND($AJ12="B", OR(BB12="B", BB12="P", BB12="O")), AND($AJ12="P", OR(BB12="P", BB12="O")), AND($AJ12="O", BB12="O")), "Sim", "Não") ) ) -> N | BD12: N | BE12: =IF($AC12="N", "N", IF($B12="Não", "Sim", IF(OR( BD12=$AC12, AND($AC12="B", OR(BD12="B", BD12="P", BD12="O")), AND($AC12="P", OR(BD12="P", BD12="O")), AND($AC12="O", BD12="O")), "Sim", "Não") ) ) -> N | BF12: N | BG12: =IF($Y12="N", "N", IF($B12="Não", "Sim", IF(OR( BF12=$Y12, AND($Y12="B", OR(BF12="B", BF12="P", BF12="O")), AND($Y12="P", OR(BF12="P", BF12="O")), AND($Y12="O", BF12="O")), "Sim", "Não") ) ) -> N | BH12: O | BI12: =IF($K12="N", "N", IF($B12="Não", "Sim", IF(OR( BH12=$K12, AND($K12="B", OR(BH12="B", BH12="P", BH12="O")), AND($K12="P", OR(BH12="P", BH12="O")), AND($K12="O", BH12="O")), "Sim", "Não") ) ) -> Sim | BJ12: N | BK12: =IF($Y12="N", "N", IF($B12="Não", "Sim", IF(OR( BJ12=$Y12, AND($Y12="B", OR(BJ12="B", BJ12="P", BJ12="O")), AND($Y12="P", OR(BJ12="P", BJ12="O")), AND($Y12="O", BJ12="O")), "Sim", "Não") ) ) -> N | BL12: N | BM12: =IF($Y12="N", "N", IF($B12="Não", "Sim", IF(OR( BL12=$Y12, AND($Y12="B", OR(BL12="B", BL12="P", BL12="O")), AND($Y12="P", OR(BL12="P", BL12="O")), AND($Y12="O", BL12="O")), "Sim", "Não") ) ) -> N | BN12: N | BO12: =IF($AJ12="N", "N", IF($B12="Não", "Sim", IF(OR( BN12=$AJ12, AND($AJ12="B", OR(BN12="B", BN12="P", BN12="O")), AND($AJ12="P", OR(BN12="P", BN12="O")), AND($AJ12="O", BN12="O")), "Sim", "Não") ) ) -> N | BP12: P | BQ12: =IF($T12="N", "N", IF($B12="Não", "Sim", IF(OR( BP12=$T12, AND($T12="B", OR(BP12="B", BP12="P", BP12="O")), AND($T12="P", OR(BP12="P", BP12="O")), AND($T12="O", BP12="O")), "Sim", "Não") ) ) -> Sim | BR12: P | BS12: =IF($I12="N", "N", IF($B12="Não", "Sim", IF(OR( BR12=$I12, AND($I12="B", OR(BR12="B", BR12="P", BR12="O")), AND($I12="P", OR(BR12="P", BR12="O")), AND($I12="O", BR12="O")), "Sim", "Não") ) ) -> Sim | BT12: P | BU12: =IF($G12="N", "N", IF($B12="Não", "Sim", IF(OR( BT12=$G12, AND($G12="B", OR(BT12="B", BT12="P", BT12="O")), AND($G12="P", OR(BT12="P", BT12="O")), AND($G12="O", BT12="O")), "Sim", "Não") ) ) -> N | BV12: B | BW12: =IF($G12="N", "N", IF($B12="Não", "Sim", IF(OR( BV12=$G12, AND($G12="B", OR(BV12="B", BV12="P", BV12="O")), AND($G12="P", OR(BV12="P", BV12="O")), AND($G12="O", BV12="O")), "Sim", "Não") ) ) -> N | BX12: P | BY12: =IF($P12="N", "N", IF($B12="Não", "Sim", IF(OR( BX12=$P12, AND($P12="B", OR(BX12="B", BX12="P", BX12="O")), AND($P12="P", OR(BX12="P", BX12="O")), AND($P12="O", BX12="O")), "Sim", "Não") ) ) -> N | BZ12: B | CA12: =IF($G12="N", "N", IF($B12="Não", "Sim", IF(OR( BZ12=$G12, AND($G12="B", OR(BZ12="B", BZ12="P", BZ12="O")), AND($G12="P", OR(BZ12="P", BZ12="O")), AND($G12="O", BZ12="O")), "Sim", "Não") ) ) -> N
B13: Não | C13: Geral | D13: Sonar: DepencyCheck | E13: N | F13: N | G13: N | H13: N | I13: N | J13: N | K13: B | L13: 1 | N13: N | O13: N | P13: N | Q13: N | R13: N | S13: N | T13: B | U13: 1 | W13: N | X13: N | Y13: N | Z13: N | AA13: B | AB13: 0 | AC13: P | AD13: 0 | AF13: N | AG13: N | AH13: B | AI13: 0 | AJ13: B | AK13: 0 | AL13: P | AM13: 0 | AO13: A | AP13: A | AQ13: A | AR13: A | AT13: D | AU13: =IF($P13="N", "N", IF($B13="Não", "Sim", IF(OR( AT13=$P13, AND($P13="B", OR(AT13="B", AT13="P", AT13="O")), AND($P13="P", OR(AT13="P", AT13="O")), AND($P13="O", AT13="O")), "Sim", "Não") ) ) -> N | AV13: B | AW13: =IF($I13="N", "N", IF($B13="Não", "Sim", IF(OR( AV13=$I13, AND($I13="B", OR(AV13="B", AV13="P", AV13="O")), AND($I13="P", OR(AV13="P", AV13="O")), AND($I13="O", AV13="O")), "Sim", "Não") ) ) -> N | AX13: B | AY13: =IF($R13="N", "N", IF($B13="Não", "Sim", IF(OR( AX13=$R13, AND($R13="B", OR(AX13="B", AX13="P", AX13="O")), AND($R13="P", OR(AX13="P", AX13="O")), AND($R13="O", AX13="O")), "Sim", "Não") ) ) -> N | AZ13: B | BA13: =IF($I13="N", "N", IF($B13="Não", "Sim", IF(OR( AZ13=$I13, AND($I13="B", OR(AZ13="B", AZ13="P", AZ13="O")), AND($I13="P", OR(AZ13="P", AZ13="O")), AND($I13="O", AZ13="O")), "Sim", "Não") ) ) -> N | BB13: B | BC13: =IF($AJ13="N", "N", IF($B13="Não", "Sim", IF(OR( BB13=$AJ13, AND($AJ13="B", OR(BB13="B", BB13="P", BB13="O")), AND($AJ13="P", OR(BB13="P", BB13="O")), AND($AJ13="O", BB13="O")), "Sim", "Não") ) ) -> Sim | BD13: P | BE13: =IF($AC13="N", "N", IF($B13="Não", "Sim", IF(OR( BD13=$AC13, AND($AC13="B", OR(BD13="B", BD13="P", BD13="O")), AND($AC13="P", OR(BD13="P", BD13="O")), AND($AC13="O", BD13="O")), "Sim", "Não") ) ) -> Sim | BF13: B | BG13: =IF($Y13="N", "N", IF($B13="Não", "Sim", IF(OR( BF13=$Y13, AND($Y13="B", OR(BF13="B", BF13="P", BF13="O")), AND($Y13="P", OR(BF13="P", BF13="O")), AND($Y13="O", BF13="O")), "Sim", "Não") ) ) -> N | BH13: P | BI13: =IF($K13="N", "N", IF($B13="Não", "Sim", IF(OR( BH13=$K13, AND($K13="B", OR(BH13="B", BH13="P", BH13="O")), AND($K13="P", OR(BH13="P", BH13="O")), AND($K13="O", BH13="O")), "Sim", "Não") ) ) -> Sim | BJ13: D | BK13: =IF($Y13="N", "N", IF($B13="Não", "Sim", IF(OR( BJ13=$Y13, AND($Y13="B", OR(BJ13="B", BJ13="P", BJ13="O")), AND($Y13="P", OR(BJ13="P", BJ13="O")), AND($Y13="O", BJ13="O")), "Sim", "Não") ) ) -> N | BL13: D | BM13: =IF($Y13="N", "N", IF($B13="Não", "Sim", IF(OR( BL13=$Y13, AND($Y13="B", OR(BL13="B", BL13="P", BL13="O")), AND($Y13="P", OR(BL13="P", BL13="O")), AND($Y13="O", BL13="O")), "Sim", "Não") ) ) -> N | BN13: B | BO13: =IF($AJ13="N", "N", IF($B13="Não", "Sim", IF(OR( BN13=$AJ13, AND($AJ13="B", OR(BN13="B", BN13="P", BN13="O")), AND($AJ13="P", OR(BN13="P", BN13="O")), AND($AJ13="O", BN13="O")), "Sim", "Não") ) ) -> Sim | BP13: B | BQ13: =IF($T13="N", "N", IF($B13="Não", "Sim", IF(OR( BP13=$T13, AND($T13="B", OR(BP13="B", BP13="P", BP13="O")), AND($T13="P", OR(BP13="P", BP13="O")), AND($T13="O", BP13="O")), "Sim", "Não") ) ) -> Sim | BR13: P | BS13: =IF($I13="N", "N", IF($B13="Não", "Sim", IF(OR( BR13=$I13, AND($I13="B", OR(BR13="B", BR13="P", BR13="O")), AND($I13="P", OR(BR13="P", BR13="O")), AND($I13="O", BR13="O")), "Sim", "Não") ) ) -> N | BT13: B | BU13: =IF($G13="N", "N", IF($B13="Não", "Sim", IF(OR( BT13=$G13, AND($G13="B", OR(BT13="B", BT13="P", BT13="O")), AND($G13="P", OR(BT13="P", BT13="O")), AND($G13="O", BT13="O")), "Sim", "Não") ) ) -> N | BV13: B | BW13: =IF($G13="N", "N", IF($B13="Não", "Sim", IF(OR( BV13=$G13, AND($G13="B", OR(BV13="B", BV13="P", BV13="O")), AND($G13="P", OR(BV13="P", BV13="O")), AND($G13="O", BV13="O")), "Sim", "Não") ) ) -> N | BX13: B | BY13: =IF($P13="N", "N", IF($B13="Não", "Sim", IF(OR( BX13=$P13, AND($P13="B", OR(BX13="B", BX13="P", BX13="O")), AND($P13="P", OR(BX13="P", BX13="O")), AND($P13="O", BX13="O")), "Sim", "Não") ) ) -> N | BZ13: B | CA13: =IF($G13="N", "N", IF($B13="Não", "Sim", IF(OR( BZ13=$G13, AND($G13="B", OR(BZ13="B", BZ13="P", BZ13="O")), AND($G13="P", OR(BZ13="P", BZ13="O")), AND($G13="O", BZ13="O")), "Sim", "Não") ) ) -> N
B14: Não | C14: Dev | D14: Boas práticas de uso de Logs | E14: B | F14: 0 | G14: B | H14: 1 | I14: P | J14: 1 | K14: O | L14: 1 | N14: B | O14: 0 | P14: B | Q14: 1 | R14: P | S14: 1 | T14: O | U14: 1 | W14: N | X14: N | Y14: N | Z14: N | AA14: N | AB14: N | AC14: N | AD14: N | AF14: N | AG14: N | AH14: N | AI14: N | AJ14: N | AK14: N | AL14: N | AM14: N | AO14: A | AP14: A | AQ14: I | AR14: I | AT14: P | AU14: =IF($P14="N", "N", IF($B14="Não", "Sim", IF(OR( AT14=$P14, AND($P14="B", OR(AT14="B", AT14="P", AT14="O")), AND($P14="P", OR(AT14="P", AT14="O")), AND($P14="O", AT14="O")), "Sim", "Não") ) ) -> Sim | AV14: O | AW14: =IF($I14="N", "N", IF($B14="Não", "Sim", IF(OR( AV14=$I14, AND($I14="B", OR(AV14="B", AV14="P", AV14="O")), AND($I14="P", OR(AV14="P", AV14="O")), AND($I14="O", AV14="O")), "Sim", "Não") ) ) -> Sim | AX14: P | AY14: =IF($R14="N", "N", IF($B14="Não", "Sim", IF(OR( AX14=$R14, AND($R14="B", OR(AX14="B", AX14="P", AX14="O")), AND($R14="P", OR(AX14="P", AX14="O")), AND($R14="O", AX14="O")), "Sim", "Não") ) ) -> Sim | AZ14: B | BA14: =IF($I14="N", "N", IF($B14="Não", "Sim", IF(OR( AZ14=$I14, AND($I14="B", OR(AZ14="B", AZ14="P", AZ14="O")), AND($I14="P", OR(AZ14="P", AZ14="O")), AND($I14="O", AZ14="O")), "Sim", "Não") ) ) -> Sim | BB14: N | BC14: =IF($AJ14="N", "N", IF($B14="Não", "Sim", IF(OR( BB14=$AJ14, AND($AJ14="B", OR(BB14="B", BB14="P", BB14="O")), AND($AJ14="P", OR(BB14="P", BB14="O")), AND($AJ14="O", BB14="O")), "Sim", "Não") ) ) -> N | BD14: N | BE14: =IF($AC14="N", "N", IF($B14="Não", "Sim", IF(OR( BD14=$AC14, AND($AC14="B", OR(BD14="B", BD14="P", BD14="O")), AND($AC14="P", OR(BD14="P", BD14="O")), AND($AC14="O", BD14="O")), "Sim", "Não") ) ) -> N | BF14: N | BG14: =IF($Y14="N", "N", IF($B14="Não", "Sim", IF(OR( BF14=$Y14, AND($Y14="B", OR(BF14="B", BF14="P", BF14="O")), AND($Y14="P", OR(BF14="P", BF14="O")), AND($Y14="O", BF14="O")), "Sim", "Não") ) ) -> N | BH14: O | BI14: =IF($K14="N", "N", IF($B14="Não", "Sim", IF(OR( BH14=$K14, AND($K14="B", OR(BH14="B", BH14="P", BH14="O")), AND($K14="P", OR(BH14="P", BH14="O")), AND($K14="O", BH14="O")), "Sim", "Não") ) ) -> Sim | BJ14: N | BK14: =IF($Y14="N", "N", IF($B14="Não", "Sim", IF(OR( BJ14=$Y14, AND($Y14="B", OR(BJ14="B", BJ14="P", BJ14="O")), AND($Y14="P", OR(BJ14="P", BJ14="O")), AND($Y14="O", BJ14="O")), "Sim", "Não") ) ) -> N | BL14: N | BM14: =IF($Y14="N", "N", IF($B14="Não", "Sim", IF(OR( BL14=$Y14, AND($Y14="B", OR(BL14="B", BL14="P", BL14="O")), AND($Y14="P", OR(BL14="P", BL14="O")), AND($Y14="O", BL14="O")), "Sim", "Não") ) ) -> N | BN14: N | BO14: =IF($AJ14="N", "N", IF($B14="Não", "Sim", IF(OR( BN14=$AJ14, AND($AJ14="B", OR(BN14="B", BN14="P", BN14="O")), AND($AJ14="P", OR(BN14="P", BN14="O")), AND($AJ14="O", BN14="O")), "Sim", "Não") ) ) -> N | BP14: P | BQ14: =IF($T14="N", "N", IF($B14="Não", "Sim", IF(OR( BP14=$T14, AND($T14="B", OR(BP14="B", BP14="P", BP14="O")), AND($T14="P", OR(BP14="P", BP14="O")), AND($T14="O", BP14="O")), "Sim", "Não") ) ) -> Sim | BR14: P | BS14: =IF($I14="N", "N", IF($B14="Não", "Sim", IF(OR( BR14=$I14, AND($I14="B", OR(BR14="B", BR14="P", BR14="O")), AND($I14="P", OR(BR14="P", BR14="O")), AND($I14="O", BR14="O")), "Sim", "Não") ) ) -> Sim | BT14: P | BU14: =IF($G14="N", "N", IF($B14="Não", "Sim", IF(OR( BT14=$G14, AND($G14="B", OR(BT14="B", BT14="P", BT14="O")), AND($G14="P", OR(BT14="P", BT14="O")), AND($G14="O", BT14="O")), "Sim", "Não") ) ) -> Sim | BV14: B | BW14: =IF($G14="N", "N", IF($B14="Não", "Sim", IF(OR( BV14=$G14, AND($G14="B", OR(BV14="B", BV14="P", BV14="O")), AND($G14="P", OR(BV14="P", BV14="O")), AND($G14="O", BV14="O")), "Sim", "Não") ) ) -> Sim | BX14: P | BY14: =IF($P14="N", "N", IF($B14="Não", "Sim", IF(OR( BX14=$P14, AND($P14="B", OR(BX14="B", BX14="P", BX14="O")), AND($P14="P", OR(BX14="P", BX14="O")), AND($P14="O", BX14="O")), "Sim", "Não") ) ) -> Sim | BZ14: O | CA14: =IF($G14="N", "N", IF($B14="Não", "Sim", IF(OR( BZ14=$G14, AND($G14="B", OR(BZ14="B", BZ14="P", BZ14="O")), AND($G14="P", OR(BZ14="P", BZ14="O")), AND($G14="O", BZ14="O")), "Sim", "Não") ) ) -> Sim
B15: Não | C15: Dev | D15: Padrões Clean Code | E15: B | F15: 0 | G15: B | H15: 0 | I15: P | J15: 1 | K15: O | L15: 1 | N15: B | O15: 0 | P15: B | Q15: 0 | R15: P | S15: 1 | T15: O | U15: 1 | W15: N | X15: N | Y15: N | Z15: N | AA15: N | AB15: N | AC15: N | AD15: N | AF15: N | AG15: N | AH15: N | AI15: N | AJ15: N | AK15: N | AL15: N | AM15: N | AO15: A | AP15: A | AQ15: I | AR15: I | AT15: P | AU15: =IF($P15="N", "N", IF($B15="Não", "Sim", IF(OR( AT15=$P15, AND($P15="B", OR(AT15="B", AT15="P", AT15="O")), AND($P15="P", OR(AT15="P", AT15="O")), AND($P15="O", AT15="O")), "Sim", "Não") ) ) -> Sim | AV15: O | AW15: =IF($I15="N", "N", IF($B15="Não", "Sim", IF(OR( AV15=$I15, AND($I15="B", OR(AV15="B", AV15="P", AV15="O")), AND($I15="P", OR(AV15="P", AV15="O")), AND($I15="O", AV15="O")), "Sim", "Não") ) ) -> Sim | AX15: P | AY15: =IF($R15="N", "N", IF($B15="Não", "Sim", IF(OR( AX15=$R15, AND($R15="B", OR(AX15="B", AX15="P", AX15="O")), AND($R15="P", OR(AX15="P", AX15="O")), AND($R15="O", AX15="O")), "Sim", "Não") ) ) -> Sim | AZ15: P | BA15: =IF($I15="N", "N", IF($B15="Não", "Sim", IF(OR( AZ15=$I15, AND($I15="B", OR(AZ15="B", AZ15="P", AZ15="O")), AND($I15="P", OR(AZ15="P", AZ15="O")), AND($I15="O", AZ15="O")), "Sim", "Não") ) ) -> Sim | BB15: N | BC15: =IF($AJ15="N", "N", IF($B15="Não", "Sim", IF(OR( BB15=$AJ15, AND($AJ15="B", OR(BB15="B", BB15="P", BB15="O")), AND($AJ15="P", OR(BB15="P", BB15="O")), AND($AJ15="O", BB15="O")), "Sim", "Não") ) ) -> N | BD15: N | BE15: =IF($AC15="N", "N", IF($B15="Não", "Sim", IF(OR( BD15=$AC15, AND($AC15="B", OR(BD15="B", BD15="P", BD15="O")), AND($AC15="P", OR(BD15="P", BD15="O")), AND($AC15="O", BD15="O")), "Sim", "Não") ) ) -> N | BF15: N | BG15: =IF($Y15="N", "N", IF($B15="Não", "Sim", IF(OR( BF15=$Y15, AND($Y15="B", OR(BF15="B", BF15="P", BF15="O")), AND($Y15="P", OR(BF15="P", BF15="O")), AND($Y15="O", BF15="O")), "Sim", "Não") ) ) -> N | BH15: P | BI15: =IF($K15="N", "N", IF($B15="Não", "Sim", IF(OR( BH15=$K15, AND($K15="B", OR(BH15="B", BH15="P", BH15="O")), AND($K15="P", OR(BH15="P", BH15="O")), AND($K15="O", BH15="O")), "Sim", "Não") ) ) -> Sim | BJ15: N | BK15: =IF($Y15="N", "N", IF($B15="Não", "Sim", IF(OR( BJ15=$Y15, AND($Y15="B", OR(BJ15="B", BJ15="P", BJ15="O")), AND($Y15="P", OR(BJ15="P", BJ15="O")), AND($Y15="O", BJ15="O")), "Sim", "Não") ) ) -> N | BL15: N | BM15: =IF($Y15="N", "N", IF($B15="Não", "Sim", IF(OR( BL15=$Y15, AND($Y15="B", OR(BL15="B", BL15="P", BL15="O")), AND($Y15="P", OR(BL15="P", BL15="O")), AND($Y15="O", BL15="O")), "Sim", "Não") ) ) -> N | BN15: N | BO15: =IF($AJ15="N", "N", IF($B15="Não", "Sim", IF(OR( BN15=$AJ15, AND($AJ15="B", OR(BN15="B", BN15="P", BN15="O")), AND($AJ15="P", OR(BN15="P", BN15="O")), AND($AJ15="O", BN15="O")), "Sim", "Não") ) ) -> N | BP15: P | BQ15: =IF($T15="N", "N", IF($B15="Não", "Sim", IF(OR( BP15=$T15, AND($T15="B", OR(BP15="B", BP15="P", BP15="O")), AND($T15="P", OR(BP15="P", BP15="O")), AND($T15="O", BP15="O")), "Sim", "Não") ) ) -> Sim | BR15: P | BS15: =IF($I15="N", "N", IF($B15="Não", "Sim", IF(OR( BR15=$I15, AND($I15="B", OR(BR15="B", BR15="P", BR15="O")), AND($I15="P", OR(BR15="P", BR15="O")), AND($I15="O", BR15="O")), "Sim", "Não") ) ) -> Sim | BT15: P | BU15: =IF($G15="N", "N", IF($B15="Não", "Sim", IF(OR( BT15=$G15, AND($G15="B", OR(BT15="B", BT15="P", BT15="O")), AND($G15="P", OR(BT15="P", BT15="O")), AND($G15="O", BT15="O")), "Sim", "Não") ) ) -> Sim | BV15: B | BW15: =IF($G15="N", "N", IF($B15="Não", "Sim", IF(OR( BV15=$G15, AND($G15="B", OR(BV15="B", BV15="P", BV15="O")), AND($G15="P", OR(BV15="P", BV15="O")), AND($G15="O", BV15="O")), "Sim", "Não") ) ) -> Sim | BX15: P | BY15: =IF($P15="N", "N", IF($B15="Não", "Sim", IF(OR( BX15=$P15, AND($P15="B", OR(BX15="B", BX15="P", BX15="O")), AND($P15="P", OR(BX15="P", BX15="O")), AND($P15="O", BX15="O")), "Sim", "Não") ) ) -> Sim | BZ15: P | CA15: =IF($G15="N", "N", IF($B15="Não", "Sim", IF(OR( BZ15=$G15, AND($G15="B", OR(BZ15="B", BZ15="P", BZ15="O")), AND($G15="P", OR(BZ15="P", BZ15="O")), AND($G15="O", BZ15="O")), "Sim", "Não") ) ) -> Sim
B16: Não | C16: Dev | D16: Padrões de projeto de software utilizando SOLID | E16: B | F16: 0 | G16: B | H16: 0 | I16: P | J16: 0 | K16: O | L16: 1 | N16: B | O16: 0 | P16: B | Q16: 0 | R16: P | S16: 0 | T16: O | U16: 1 | W16: N | X16: N | Y16: N | Z16: N | AA16: N | AB16: N | AC16: N | AD16: N | AF16: N | AG16: N | AH16: N | AI16: N | AJ16: N | AK16: N | AL16: N | AM16: N | AO16: A | AP16: A | AQ16: I | AR16: I | AT16: P | AU16: =IF($P16="N", "N", IF($B16="Não", "Sim", IF(OR( AT16=$P16, AND($P16="B", OR(AT16="B", AT16="P", AT16="O")), AND($P16="P", OR(AT16="P", AT16="O")), AND($P16="O", AT16="O")), "Sim", "Não") ) ) -> Sim | AV16: P | AW16: =IF($I16="N", "N", IF($B16="Não", "Sim", IF(OR( AV16=$I16, AND($I16="B", OR(AV16="B", AV16="P", AV16="O")), AND($I16="P", OR(AV16="P", AV16="O")), AND($I16="O", AV16="O")), "Sim", "Não") ) ) -> Sim | AX16: P | AY16: =IF($R16="N", "N", IF($B16="Não", "Sim", IF(OR( AX16=$R16, AND($R16="B", OR(AX16="B", AX16="P", AX16="O")), AND($R16="P", OR(AX16="P", AX16="O")), AND($R16="O", AX16="O")), "Sim", "Não") ) ) -> Sim | AZ16: P | BA16: =IF($I16="N", "N", IF($B16="Não", "Sim", IF(OR( AZ16=$I16, AND($I16="B", OR(AZ16="B", AZ16="P", AZ16="O")), AND($I16="P", OR(AZ16="P", AZ16="O")), AND($I16="O", AZ16="O")), "Sim", "Não") ) ) -> Sim | BB16: N | BC16: =IF($AJ16="N", "N", IF($B16="Não", "Sim", IF(OR( BB16=$AJ16, AND($AJ16="B", OR(BB16="B", BB16="P", BB16="O")), AND($AJ16="P", OR(BB16="P", BB16="O")), AND($AJ16="O", BB16="O")), "Sim", "Não") ) ) -> N | BD16: N | BE16: =IF($AC16="N", "N", IF($B16="Não", "Sim", IF(OR( BD16=$AC16, AND($AC16="B", OR(BD16="B", BD16="P", BD16="O")), AND($AC16="P", OR(BD16="P", BD16="O")), AND($AC16="O", BD16="O")), "Sim", "Não") ) ) -> N | BF16: N | BG16: =IF($Y16="N", "N", IF($B16="Não", "Sim", IF(OR( BF16=$Y16, AND($Y16="B", OR(BF16="B", BF16="P", BF16="O")), AND($Y16="P", OR(BF16="P", BF16="O")), AND($Y16="O", BF16="O")), "Sim", "Não") ) ) -> N | BH16: P | BI16: =IF($K16="N", "N", IF($B16="Não", "Sim", IF(OR( BH16=$K16, AND($K16="B", OR(BH16="B", BH16="P", BH16="O")), AND($K16="P", OR(BH16="P", BH16="O")), AND($K16="O", BH16="O")), "Sim", "Não") ) ) -> Sim | BJ16: N | BK16: =IF($Y16="N", "N", IF($B16="Não", "Sim", IF(OR( BJ16=$Y16, AND($Y16="B", OR(BJ16="B", BJ16="P", BJ16="O")), AND($Y16="P", OR(BJ16="P", BJ16="O")), AND($Y16="O", BJ16="O")), "Sim", "Não") ) ) -> N | BL16: N | BM16: =IF($Y16="N", "N", IF($B16="Não", "Sim", IF(OR( BL16=$Y16, AND($Y16="B", OR(BL16="B", BL16="P", BL16="O")), AND($Y16="P", OR(BL16="P", BL16="O")), AND($Y16="O", BL16="O")), "Sim", "Não") ) ) -> N | BN16: N | BO16: =IF($AJ16="N", "N", IF($B16="Não", "Sim", IF(OR( BN16=$AJ16, AND($AJ16="B", OR(BN16="B", BN16="P", BN16="O")), AND($AJ16="P", OR(BN16="P", BN16="O")), AND($AJ16="O", BN16="O")), "Sim", "Não") ) ) -> N | BP16: P | BQ16: =IF($T16="N", "N", IF($B16="Não", "Sim", IF(OR( BP16=$T16, AND($T16="B", OR(BP16="B", BP16="P", BP16="O")), AND($T16="P", OR(BP16="P", BP16="O")), AND($T16="O", BP16="O")), "Sim", "Não") ) ) -> Sim | BR16: P | BS16: =IF($I16="N", "N", IF($B16="Não", "Sim", IF(OR( BR16=$I16, AND($I16="B", OR(BR16="B", BR16="P", BR16="O")), AND($I16="P", OR(BR16="P", BR16="O")), AND($I16="O", BR16="O")), "Sim", "Não") ) ) -> Sim | BT16: B | BU16: =IF($G16="N", "N", IF($B16="Não", "Sim", IF(OR( BT16=$G16, AND($G16="B", OR(BT16="B", BT16="P", BT16="O")), AND($G16="P", OR(BT16="P", BT16="O")), AND($G16="O", BT16="O")), "Sim", "Não") ) ) -> Sim | BV16: P | BW16: =IF($G16="N", "N", IF($B16="Não", "Sim", IF(OR( BV16=$G16, AND($G16="B", OR(BV16="B", BV16="P", BV16="O")), AND($G16="P", OR(BV16="P", BV16="O")), AND($G16="O", BV16="O")), "Sim", "Não") ) ) -> Sim | BX16: P | BY16: =IF($P16="N", "N", IF($B16="Não", "Sim", IF(OR( BX16=$P16, AND($P16="B", OR(BX16="B", BX16="P", BX16="O")), AND($P16="P", OR(BX16="P", BX16="O")), AND($P16="O", BX16="O")), "Sim", "Não") ) ) -> Sim | BZ16: P | CA16: =IF($G16="N", "N", IF($B16="Não", "Sim", IF(OR( BZ16=$G16, AND($G16="B", OR(BZ16="B", BZ16="P", BZ16="O")), AND($G16="P", OR(BZ16="P", BZ16="O")), AND($G16="O", BZ16="O")), "Sim", "Não") ) ) -> Sim
B17: Não | C17: Geral | D17: GIT | E17: B | F17: 0 | G17: B | H17: 1 | I17: P | J17: 1 | K17: P | L17: 1 | N17: B | O17: 0 | P17: B | Q17: 1 | R17: P | S17: 1 | T17: P | U17: 1 | W17: B | X17: 0 | Y17: B | Z17: 0 | AA17: P | AB17: 0 | AC17: P | AD17: 0 | AF17: B | AG17: 0 | AH17: B | AI17: 1 | AJ17: P | AK17: 1 | AL17: P | AM17: 1 | AO17: A | AP17: A | AQ17: A | AR17: A | AT17: P | AU17: =IF($P17="N", "N", IF($B17="Não", "Sim", IF(OR( AT17=$P17, AND($P17="B", OR(AT17="B", AT17="P", AT17="O")), AND($P17="P", OR(AT17="P", AT17="O")), AND($P17="O", AT17="O")), "Sim", "Não") ) ) -> Sim | AV17: P | AW17: =IF($I17="N", "N", IF($B17="Não", "Sim", IF(OR( AV17=$I17, AND($I17="B", OR(AV17="B", AV17="P", AV17="O")), AND($I17="P", OR(AV17="P", AV17="O")), AND($I17="O", AV17="O")), "Sim", "Não") ) ) -> Sim | AX17: P | AY17: =IF($R17="N", "N", IF($B17="Não", "Sim", IF(OR( AX17=$R17, AND($R17="B", OR(AX17="B", AX17="P", AX17="O")), AND($R17="P", OR(AX17="P", AX17="O")), AND($R17="O", AX17="O")), "Sim", "Não") ) ) -> Sim | AZ17: P | BA17: =IF($I17="N", "N", IF($B17="Não", "Sim", IF(OR( AZ17=$I17, AND($I17="B", OR(AZ17="B", AZ17="P", AZ17="O")), AND($I17="P", OR(AZ17="P", AZ17="O")), AND($I17="O", AZ17="O")), "Sim", "Não") ) ) -> Sim | BB17: P | BC17: =IF($AJ17="N", "N", IF($B17="Não", "Sim", IF(OR( BB17=$AJ17, AND($AJ17="B", OR(BB17="B", BB17="P", BB17="O")), AND($AJ17="P", OR(BB17="P", BB17="O")), AND($AJ17="O", BB17="O")), "Sim", "Não") ) ) -> Sim | BD17: P | BE17: =IF($AC17="N", "N", IF($B17="Não", "Sim", IF(OR( BD17=$AC17, AND($AC17="B", OR(BD17="B", BD17="P", BD17="O")), AND($AC17="P", OR(BD17="P", BD17="O")), AND($AC17="O", BD17="O")), "Sim", "Não") ) ) -> Sim | BF17: P | BG17: =IF($Y17="N", "N", IF($B17="Não", "Sim", IF(OR( BF17=$Y17, AND($Y17="B", OR(BF17="B", BF17="P", BF17="O")), AND($Y17="P", OR(BF17="P", BF17="O")), AND($Y17="O", BF17="O")), "Sim", "Não") ) ) -> Sim | BH17: P | BI17: =IF($K17="N", "N", IF($B17="Não", "Sim", IF(OR( BH17=$K17, AND($K17="B", OR(BH17="B", BH17="P", BH17="O")), AND($K17="P", OR(BH17="P", BH17="O")), AND($K17="O", BH17="O")), "Sim", "Não") ) ) -> Sim | BJ17: B | BK17: =IF($Y17="N", "N", IF($B17="Não", "Sim", IF(OR( BJ17=$Y17, AND($Y17="B", OR(BJ17="B", BJ17="P", BJ17="O")), AND($Y17="P", OR(BJ17="P", BJ17="O")), AND($Y17="O", BJ17="O")), "Sim", "Não") ) ) -> Sim | BL17: B | BM17: =IF($Y17="N", "N", IF($B17="Não", "Sim", IF(OR( BL17=$Y17, AND($Y17="B", OR(BL17="B", BL17="P", BL17="O")), AND($Y17="P", OR(BL17="P", BL17="O")), AND($Y17="O", BL17="O")), "Sim", "Não") ) ) -> Sim | BN17: P | BO17: =IF($AJ17="N", "N", IF($B17="Não", "Sim", IF(OR( BN17=$AJ17, AND($AJ17="B", OR(BN17="B", BN17="P", BN17="O")), AND($AJ17="P", OR(BN17="P", BN17="O")), AND($AJ17="O", BN17="O")), "Sim", "Não") ) ) -> Sim | BP17: P | BQ17: =IF($T17="N", "N", IF($B17="Não", "Sim", IF(OR( BP17=$T17, AND($T17="B", OR(BP17="B", BP17="P", BP17="O")), AND($T17="P", OR(BP17="P", BP17="O")), AND($T17="O", BP17="O")), "Sim", "Não") ) ) -> Sim | BR17: O | BS17: =IF($I17="N", "N", IF($B17="Não", "Sim", IF(OR( BR17=$I17, AND($I17="B", OR(BR17="B", BR17="P", BR17="O")), AND($I17="P", OR(BR17="P", BR17="O")), AND($I17="O", BR17="O")), "Sim", "Não") ) ) -> Sim | BT17: P | BU17: =IF($G17="N", "N", IF($B17="Não", "Sim", IF(OR( BT17=$G17, AND($G17="B", OR(BT17="B", BT17="P", BT17="O")), AND($G17="P", OR(BT17="P", BT17="O")), AND($G17="O", BT17="O")), "Sim", "Não") ) ) -> Sim | BV17: P | BW17: =IF($G17="N", "N", IF($B17="Não", "Sim", IF(OR( BV17=$G17, AND($G17="B", OR(BV17="B", BV17="P", BV17="O")), AND($G17="P", OR(BV17="P", BV17="O")), AND($G17="O", BV17="O")), "Sim", "Não") ) ) -> Sim | BX17: P | BY17: =IF($P17="N", "N", IF($B17="Não", "Sim", IF(OR( BX17=$P17, AND($P17="B", OR(BX17="B", BX17="P", BX17="O")), AND($P17="P", OR(BX17="P", BX17="O")), AND($P17="O", BX17="O")), "Sim", "Não") ) ) -> Sim | BZ17: O | CA17: =IF($G17="N", "N", IF($B17="Não", "Sim", IF(OR( BZ17=$G17, AND($G17="B", OR(BZ17="B", BZ17="P", BZ17="O")), AND($G17="P", OR(BZ17="P", BZ17="O")), AND($G17="O", BZ17="O")), "Sim", "Não") ) ) -> Sim
